<?xml version="1.0"?>
<robot name="ttk4900_orca">
  
  <material name="offwhite">
    <color rgba="0.94 0.92 0.87 1.0"/>
  </material>
  
  <link name="base_link">
    <!-- <inertial>
      <origin xyz="0.0 0.0 0.0" rpy="0.0 0.0 0.0"/>
      <mass value="15"/>
      <inertia ixx="0.1" ixy="0.0" ixz="0.0" iyy="0.1" iyz="0.0" izz="0.1"/>
    </inertial> -->
    <visual name="base_visual">
      <origin xyz="0.0 0.0 0.0" rpy="0.0 0.0 0.0"/>
      <geometry>
        <box size="1.8 0.135 0.09"/>
      </geometry>
      <material name="offwhite"/>
    </visual>
    <collision>
      <origin xyz="0.0 0.0 0.0" rpy="0.0 0.0 0.0"/>
      <geometry>
        <box size="1.8 0.135 0.09"/>
      </geometry>
    </collision>
  </link>

  <link name="torso_link0">
    <inertial>
      <origin xyz="0.0 0.0 0.0" rpy="0.0 0.0 0.0"/>
      <mass value="8.0"/>
      <inertia ixx="0.1" ixy="0.0" ixz="0.0" iyy="0.1" iyz="0.0" izz="0.1"/>
    </inertial>
    <visual name="torso_visual0">
      <origin xyz="0.085 0.0 0.06" rpy="0.0 0.0 0.0"/>
      <geometry>
        <box size="0.17 0.1 0.12"/>
      </geometry>
      <material name="offwhite"/>
    </visual>
    <collision>
      <origin xyz="0.085 0.0 0.06" rpy="0.0 0.0 0.0"/>
      <geometry>
        <box size="0.17 0.1 0.12"/>
      </geometry>
    </collision>
  </link>

  <link name="torso_link1">
    <inertial>
      <origin xyz="0.0 0.0 0.0" rpy="0.0 0.0 0.0"/>
      <mass value="0.2"/>
      <inertia ixx="0.1" ixy="0.0" ixz="0.0" iyy="0.1" iyz="0.0" izz="0.1"/>
    </inertial>
    <visual name="torso_visual1">
      <origin xyz="0.04 0.0 0.07" rpy="0.0 0.0 0.0"/>
      <geometry>
        <box size="0.04 0.1 0.14"/>
      </geometry>
      <material name="offwhite"/>
    </visual>
    <collision>
      <origin xyz="0.04 0.0 0.07" rpy="0.0 0.0 0.0"/>
      <geometry>
        <box size="0.04 0.1 0.14"/>
      </geometry>
    </collision>
  </link>

  <joint name="joint_base_torso" type="prismatic">
    <origin xyz="-0.9 0.0 0.045" rpy="0.0 0.0 0.0"/>
    <parent link="base_link"/>
    <child link="torso_link0"/>
    <axis xyz="-1 0.0 0.0"/>
    <limit lower="-1.40" upper="0" effort="100" velocity="0.1"/>
  </joint>

  <joint name="joint_t0t1" type="fixed">
    <origin xyz="0.11 0.0 0.12" rpy="0.0 0.0 0.0"/>
    <parent link="torso_link0"/>
    <child link="torso_link1"/>
    <axis xyz="0.0 0.0 0.0"/>
    <limit lower="0.0" upper="0.0" effort="0.0" velocity="0.0"/>
  </joint>

  <link name="link_upper_arm">
    <inertial>
      <origin xyz="0.0 0.0 0.0" rpy="0.0 0.0 0.0"/>
      <mass value="2.5"/>
      <inertia ixx="0.1" ixy="0.0" ixz="0.0" iyy="0.1" iyz="0.0" izz="0.1"/>
    </inertial>
    <visual name="upper_arm_visual">
      <origin xyz="0.0 0.0 0.12" rpy="0.0 0.0 0.0"/>
      <geometry>
        <box size="0.04 0.08 0.24"/>
      </geometry>
      <material name="offwhite"/>
    </visual>
    <collision>
      <origin xyz="-0.0 0.0 0.12" rpy="0.0 0.0 0.0"/>
      <geometry>
        <box size="0.04 0.08 0.24"/>
      </geometry>
    </collision>
  </link>

  <joint name="joint_torso_upper_arm" type="revolute">
    <origin xyz="0.0 0.0 0.09" rpy="0.0 0.0 0.0"/>
    <parent link="torso_link1"/>
    <child link="link_upper_arm"/>
    <axis xyz="-1 0.0 0.0"/>
    <limit lower="-1.5" upper="1.5" effort="100" velocity="0.17"/>
  </joint>

  <link name="link_lower_arm">
    <inertial>
      <origin xyz="0.0 0.0 0.0" rpy="0.0 0.0 0.0"/>
      <mass value="1.5"/>
      <inertia ixx="0.1" ixy="0.0" ixz="0.0" iyy="0.1" iyz="0.0" izz="0.1"/>
    </inertial>
    <visual name="upper_arm_visual">
      <origin xyz="0.0 0.0 0.1225" rpy="0.0 0.0 0.0"/>
      <geometry>
        <box size="0.03 0.06 0.245"/>
      </geometry>
      <material name="offwhite"/>
    </visual>
    <collision>
      <origin xyz="0.0 0.0 0.1225" rpy="0.0 0.0 0.0"/>
      <geometry>
        <box size="0.03 0.06 0.245"/>
      </geometry>
    </collision>
  </link>

  <joint name="joint_upper_lower_arm" type="revolute">
    <origin xyz="0.035 0.0 0.24" rpy="0.0 0.0 0.0"/>
    <parent link="link_upper_arm"/>
    <child link="link_lower_arm"/>
    <axis xyz="1 0.0 0.0"/>
    <limit lower="-2.5" upper="2.5" effort="100" velocity="0.17"/>
  </joint>

  <link name="link_hand">
    <inertial>
      <origin xyz="0.0 0.0 0.0" rpy="0.0 0.0 0.0"/>
      <mass value="0.5"/>
      <inertia ixx="0.1" ixy="0.0" ixz="0.0" iyy="0.1" iyz="0.0" izz="0.1"/>
    </inertial>
    <visual name="hand_visual">
      <origin xyz="-0.0325 0 -0.01" rpy="0.0 0.0 0.0"/>
      <geometry>
        <box size="0.065 0.055 0.095"/>
      </geometry>
      <material name="offwhite"/>
    </visual>
    <collision>
      <origin xyz="-0.0325 0 -0.01" rpy="0.0 0.0 0.0"/>
      <geometry>
        <box size="0.065 0.055 0.095"/>
      </geometry>
    </collision>
  </link>

  <joint name="joint_lower_arm_hand" type="revolute">
    <origin xyz="-0.015 0.0 0.245" rpy="0.0 0.0 0.0"/>
    <parent link="link_lower_arm"/>
    <child link="link_hand"/>
    <axis xyz="-1 0.0 0.0"/>
    <limit lower="-8" upper="2.5" effort="100" velocity="0.17"/>
  </joint>

  <link name="link_twist">
    <inertial>
      <origin xyz="0.0 0.0 0.0" rpy="0.0 0.0 0.0"/>
      <mass value="0.2"/>
      <inertia ixx="0.1" ixy="0.0" ixz="0.0" iyy="0.1" iyz="0.0" izz="0.1"/>
    </inertial>
    <visual name="twist_visual">
      <origin xyz="0 0 0.0115" rpy="0.0 0.0 0.0"/>
      <geometry>
        <box size="0.14 0.045 0.023"/>
      </geometry>
      <material name="brown">
        <color rgba="0.1 0.05 0.03 1.0"/>
      </material>
    </visual>
    <collision>
      <origin xyz="0 0 0.0115" rpy="0.0 0.0 0.0"/>
      <geometry>
        <box size="0.14 0.045 0.023"/>
      </geometry>
    </collision>
  </link>

  <joint name="joint_hand_twist" type="continuous">
    <origin xyz="-0.0325 0.0 0.042" rpy="0.0 0.0 0.0"/>
    <parent link="link_hand"/>
    <child link="link_twist"/>
    <axis xyz="0.0 0.0 1"/>
    <!-- <limit lower="0.0" upper="0.0" effort="100" velocity="3"/> -->
    <limit effort="100" velocity="3"/>
  </joint>

  <link name="link_gripper0">
    <inertial>
      <origin xyz="0.0 0.0 0.0" rpy="0.0 0.0 0.0"/>
      <mass value="0.03"/>
      <inertia ixx="0.005" ixy="0.0" ixz="0.0" iyy="0.05" iyz="0.0" izz="0.05"/>
    </inertial>
    <visual name="gripper0_visual">
      <origin xyz="-0.019 0.0 0.075" rpy="0.0 0.0 0.0"/>
      <geometry>
        <!-- <box size="0.038 0.013 0.02"/>  -->
        <box size="0.038 0.013 0.15"/> 
      </geometry>
      <material name="light_gray">
        <color rgba="0.63 0.63 0.63 1.0"/>
      </material>
    </visual>
    <collision>
      <origin xyz="-0.019 0.0 0.075" rpy="0.0 0.0 0.0"/>
      <geometry>
        <!-- <box size="0.038 0.013 0.02"/> -->
        <box size="0.038 0.013 0.15"/> 
      </geometry>
    </collision>
  </link>

  <joint name="joint_twist_gripper0" type="prismatic">
    <origin xyz="0.0 0.0 0.023" rpy="0.0 0.0 0.0"/>
    <parent link="link_twist"/>
    <child link="link_gripper0"/>
    <axis xyz="-1 0.0 0.0"/>
    <limit lower="0.0" upper="0.04" effort="100" velocity="0.01"/>
  </joint>

  <link name="link_gripper1">
    <inertial>
      <origin xyz="0.0 0.0 0.0" rpy="0.0 0.0 0.0"/>
      <mass value="0.03"/>
      <inertia ixx="0.005" ixy="0.0" ixz="0.0" iyy="0.05" iyz="0.0" izz="0.05"/>
    </inertial>
    <visual name="gripper1_visual">
      <origin xyz="0.019 0.0 0.075" rpy="0.0 0.0 0.0"/>
      <geometry>
        <!-- <box size="0.038 0.013 0.02"/> -->
        <box size="0.038 0.013 0.15"/> 
      </geometry>
      <material name="light_gray">
        <color rgba="0.63 0.63 0.63 1.0"/>
      </material>
    </visual>
    <collision>
      <origin xyz="0.019 0.0 0.075" rpy="0.0 0.0 0.0"/>
      <geometry>
        <!-- <box size="0.038 0.013 0.02"/> -->
        <box size="0.038 0.013 0.15"/> 
      </geometry>
    </collision>
  </link>

  <joint name="joint_twist_gripper1" type="prismatic">
    <origin xyz="0.0 0.0 0.023" rpy="0.0 0.0 0.0"/>
    <parent link="link_twist"/>
    <child link="link_gripper1"/>
    <axis xyz="1 0.0 0.0"/>
    <limit lower="0.0" upper="0.04" effort="100" velocity="0.01"/>
  </joint>


</robot>
